Workbook

Sheet LEEME
B2: ARCHIVO DE DEMOSTRACION — DATOS COMPLETAMENTE FICTICIOS
B4: Empresa: Agrodrones del Bajio S.A. de C.V. (EMPRESA FICTICIA)
B6: Clientes, modelos, numeros de serie, importes, fechas y gastos son inventados.
B7: Este archivo NO contiene informacion de ningun cliente real.
B9: Proposito: demostrar la aplicacion y ejercitar todos sus modulos y casos limite.
B11: Casos deliberadamente incluidos:
B12: - Las seis lineas de producto, incluida una unidad Demo sin precio de venta.
B13: - Los cinco tramos de antiguedad de cartera con saldo, el de 91-180 incluido.
B14: - Base de medicion mixta: algunas ventas con dias de credito y otras sin el.
B15: - Abonos multiples por venta, con fecha y metodo de pago.
B16: - Un sobrecobro (V-018), una venta sin fecha (V-025).
B17: - Gastos fijos y variables a lo largo de nueve meses.

Sheet ventas
A1: folio | B1: fecha | C1: linea | D1: cliente | E1: modelo | F1: serie | G1: costo_unitario | H1: precio_venta | I1: comision_pct | J1: comision_base | K1: dias_credito | L1: condicion | M1: vendedor | N1: utilidad_bruta | O1: margen_pct | P1: cobrado | Q1: saldo | R1: notas
A2: V-000 | B2: 15/03/2026 | C2: Equipo | D2: EJEMPLO — Cliente Demostrativo | E2: AX-55 | F2: FIC-EJEMPLO | G2: 190000 | H2: 265000 | I2: 0.05 | J2: Venta | K2: 90 | L2: Credito | M2: Nombre vendedor | N2: =IFERROR(H2-G2,"") -> 75000 | O2: =IFERROR(N2/H2,"") -> 0.28301887 | P2: =IFERROR(SUMIF(cobranza!$B$3:$B$1000,A2,cobranza!$D$3:$D$1000),0) -> 0 | Q2: =IFERROR(H2-P2,"") -> 265000
A3: V-001 | B3: 46036 | C3: Equipo | D3: Agricola San Lorenzo | E3: AX-100 | F3: FIC-A100-0001 | G3: 380000 | H3: 520000 | I3: 0.05 | J3: Venta | L3: Credito | M3: Mariana Olvera | N3: =IFERROR(H3-G3,"") -> 140000 | O3: =IFERROR(N3/H3,"") -> 0.26923077 | P3: =IF($A3="","",IF(COUNTIF($A$3:$A3,$A3)=1,SUMIF(cobranza!$B$3:$B$1000,$A3,cobranza!$D$3:$D$1000),"↑")) -> 200000 | Q3: =IF($A3="","",IF(COUNTIF($A$3:$A3,$A3)=1,SUMIFS($H$3:$H$1000,$A$3:$A$1000,$A3,$C$3:$C$1000,"<>Demo")-P3,"↑")) -> 320000
A4: V-002 | B4: 46050 | C4: Equipo | D4: Rancho El Mezquital | E4: AX-55 | F4: FIC-A055-0002 | G4: 190000 | H4: 265000 | J4: No aplica | L4: Credito | M4: Tomas Iriarte | N4: =IFERROR(H4-G4,"") -> 75000 | O4: =IFERROR(N4/H4,"") -> 0.28301887 | P4: =IF($A4="","",IF(COUNTIF($A$3:$A4,$A4)=1,SUMIF(cobranza!$B$3:$B$1000,$A4,cobranza!$D$3:$D$1000),"↑")) -> 90000 | Q4: =IF($A4="","",IF(COUNTIF($A$3:$A4,$A4)=1,SUMIFS($H$3:$H$1000,$A$3:$A$1000,$A4,$C$3:$C$1000,"<>Demo")-P4,"↑")) -> 175000
A5: V-003 | B5: 46062 | C5: Equipo | D5: Productores Unidos del Valle | E5: AX-70 | F5: FIC-A070-0003 | G5: 295000 | H5: 385000 | I5: 0.05 | J5: Venta | L5: Credito | M5: Mariana Olvera | N5: =IFERROR(H5-G5,"") -> 90000 | O5: =IFERROR(N5/H5,"") -> 0.23376623 | P5: =IF($A5="","",IF(COUNTIF($A$3:$A5,$A5)=1,SUMIF(cobranza!$B$3:$B$1000,$A5,cobranza!$D$3:$D$1000),"↑")) -> 210000 | Q5: =IF($A5="","",IF(COUNTIF($A$3:$A5,$A5)=1,SUMIFS($H$3:$H$1000,$A$3:$A$1000,$A5,$C$3:$C$1000,"<>Demo")-P5,"↑")) -> 175000
A6: V-004 | B6: 46062 | C6: Accesorios | D6: Vivero Santa Cruz | E6: Antena RTK | F6: FIC-ANT-0004 | G6: 28000 | H6: 42000 | J6: No aplica | L6: Contado | M6: Mariana Olvera | N6: =IFERROR(H6-G6,"") -> 14000 | O6: =IFERROR(N6/H6,"") -> 0.33333333 | P6: =IF($A6="","",IF(COUNTIF($A$3:$A6,$A6)=1,SUMIF(cobranza!$B$3:$B$1000,$A6,cobranza!$D$3:$D$1000),"↑")) -> 42000 | Q6: =IF($A6="","",IF(COUNTIF($A$3:$A6,$A6)=1,SUMIFS($H$3:$H$1000,$A$3:$A$1000,$A6,$C$3:$C$1000,"<>Demo")-P6,"↑")) -> 0
A7: V-005 | B7: 46073 | C7: Equipo | D7: Hortalizas La Esperanza | E7: AX-25 | F7: FIC-A025-0005 | G7: 128000 | H7: 178000 | J7: No aplica | K7: 60 | L7: Contado | M7: Tomas Iriarte | N7: =IFERROR(H7-G7,"") -> 50000 | O7: =IFERROR(N7/H7,"") -> 0.28089888 | P7: =IF($A7="","",IF(COUNTIF($A$3:$A7,$A7)=1,SUMIF(cobranza!$B$3:$B$1000,$A7,cobranza!$D$3:$D$1000),"↑")) -> 178000 | Q7: =IF($A7="","",IF(COUNTIF($A$3:$A7,$A7)=1,SUMIFS($H$3:$H$1000,$A$3:$A$1000,$A7,$C$3:$C$1000,"<>Demo")-P7,"↑")) -> 0
A8: V-006 | B8: 46084 | C8: Demo | D8: Unidad demostrativa interna | E8: AX-70 | F8: FIC-A070-0006 | G8: 295000 | J8: No aplica | L8: Contado | N8: =IFERROR(H8-G8,"") -> -295000 | O8: =IFERROR(N8/H8,"") | P8: =IF($A8="","",IF(COUNTIF($A$3:$A8,$A8)=1,SUMIF(cobranza!$B$3:$B$1000,$A8,cobranza!$D$3:$D$1000),"↑")) -> 295000 | Q8: =IF($A8="","",IF(COUNTIF($A$3:$A8,$A8)=1,SUMIFS($H$3:$H$1000,$A$3:$A$1000,$A8,$C$3:$C$1000,"<>Demo")-P8,"↑")) -> -295000 | R8: Unidad demostrativa, excluida del analisis de venta
A9: V-007 | B9: 46099 | C9: Equipo | D9: Campos de Altamira | E9: AX-100 | F9: FIC-A100-0007 | G9: 380000 | H9: 520000 | I9: 0.07 | J9: Venta | K9: 90 | L9: Credito | M9: Mariana Olvera | N9: =IFERROR(H9-G9,"") -> 140000 | O9: =IFERROR(N9/H9,"") -> 0.26923077 | P9: =IF($A9="","",IF(COUNTIF($A$3:$A9,$A9)=1,SUMIF(cobranza!$B$3:$B$1000,$A9,cobranza!$D$3:$D$1000),"↑")) -> 295000 | Q9: =IF($A9="","",IF(COUNTIF($A$3:$A9,$A9)=1,SUMIFS($H$3:$H$1000,$A$3:$A$1000,$A9,$C$3:$C$1000,"<>Demo")-P9,"↑")) -> 225000
A10: V-008 | B10: 46119 | C10: Equipo | D10: Ing. Ramon Tellez | E10: AX-55 | F10: FIC-A055-0008 | G10: 190000 | H10: 265000 | J10: No aplica | K10: 90 | L10: Credito | M10: Tomas Iriarte | N10: =IFERROR(H10-G10,"") -> 75000 | O10: =IFERROR(N10/H10,"") -> 0.28301887 | P10: =IF($A10="","",IF(COUNTIF($A$3:$A10,$A10)=1,SUMIF(cobranza!$B$3:$B$1000,$A10,cobranza!$D$3:$D$1000),"↑")) -> 124000 | Q10: =IF($A10="","",IF(COUNTIF($A$3:$A10,$A10)=1,SUMIFS($H$3:$H$1000,$A$3:$A$1000,$A10,$C$3:$C$1000,"<>Demo")-P10,"↑")) -> 165000
A11: V-008 | B11: 46119 | C11: Accesorios | D11: Ing. Ramon Tellez | E11: Centrifuga dual | F11: FIC-CEN-0009 | G11: 14500 | H11: 24000 | J11: No aplica | M11: Tomas Iriarte | N11: =IFERROR(H11-G11,"") -> 9500 | O11: =IFERROR(N11/H11,"") -> 0.39583333 | P11: =IF($A11="","",IF(COUNTIF($A$3:$A11,$A11)=1,SUMIF(cobranza!$B$3:$B$1000,$A11,cobranza!$D$3:$D$1000),"↑")) -> ↑ | Q11: =IF($A11="","",IF(COUNTIF($A$3:$A11,$A11)=1,SUMIFS($H$3:$H$1000,$A$3:$A$1000,$A11,$C$3:$C$1000,"<>Demo")-P11,"↑")) -> ↑
A12: V-010 | B12: 46134 | C12: Servicio | D12: Agroservicios Tepeyac | E12: Aplicacion 50 ha | G12: 18000 | H12: 32000 | J12: No aplica | L12: Contado | M12: Mariana Olvera | N12: =IFERROR(H12-G12,"") -> 14000 | O12: =IFERROR(N12/H12,"") -> 0.4375 | P12: =IF($A12="","",IF(COUNTIF($A$3:$A12,$A12)=1,SUMIF(cobranza!$B$3:$B$1000,$A12,cobranza!$D$3:$D$1000),"↑")) -> 32000 | Q12: =IF($A12="","",IF(COUNTIF($A$3:$A12,$A12)=1,SUMIFS($H$3:$H$1000,$A$3:$A$1000,$A12,$C$3:$C$1000,"<>Demo")-P12,"↑")) -> 0
A13: V-011 | B13: 46153 | C13: Equipo | D13: Semillas del Norte | E13: AX-70 | F13: FIC-A070-0011 | G13: 295000 | H13: 385000 | I13: 0.05 | J13: Venta | K13: 90 | L13: Credito | M13: Mariana Olvera | N13: =IFERROR(H13-G13,"") -> 90000 | O13: =IFERROR(N13/H13,"") -> 0.23376623 | P13: =IF($A13="","",IF(COUNTIF($A$3:$A13,$A13)=1,SUMIF(cobranza!$B$3:$B$1000,$A13,cobranza!$D$3:$D$1000),"↑")) -> 290000 | Q13: =IF($A13="","",IF(COUNTIF($A$3:$A13,$A13)=1,SUMIFS($H$3:$H$1000,$A$3:$A$1000,$A13,$C$3:$C$1000,"<>Demo")-P13,"↑")) -> 95000
A14: V-012 | B14: 46168 | C14: Capacitacion | D14: Campos de Altamira | E14: Curso piloto certificado | G14: 4500 | H14: 12000 | J14: No aplica | L14: Contado | M14: Tomas Iriarte | N14: =IFERROR(H14-G14,"") -> 7500 | O14: =IFERROR(N14/H14,"") -> 0.625 | P14: =IF($A14="","",IF(COUNTIF($A$3:$A14,$A14)=1,SUMIF(cobranza!$B$3:$B$1000,$A14,cobranza!$D$3:$D$1000),"↑")) -> 12000 | Q14: =IF($A14="","",IF(COUNTIF($A$3:$A14,$A14)=1,SUMIFS($H$3:$H$1000,$A$3:$A$1000,$A14,$C$3:$C$1000,"<>Demo")-P14,"↑")) -> 0
A15: V-013 | B15: 46177 | C15: Equipo | D15: Finca Los Alamos | E15: AX-25 | F15: FIC-A025-0013 | G15: 128000 | H15: 178000 | J15: No aplica | L15: Credito | M15: Tomas Iriarte | N15: =IFERROR(H15-G15,"") -> 50000 | O15: =IFERROR(N15/H15,"") -> 0.28089888 | P15: =IF($A15="","",IF(COUNTIF($A$3:$A15,$A15)=1,SUMIF(cobranza!$B$3:$B$1000,$A15,cobranza!$D$3:$D$1000),"↑")) -> 60000 | Q15: =IF($A15="","",IF(COUNTIF($A$3:$A15,$A15)=1,SUMIFS($H$3:$H$1000,$A$3:$A$1000,$A15,$C$3:$C$1000,"<>Demo")-P15,"↑")) -> 118000
A16: V-014 | B16: 46192 | C16: Refacciones | D16: Rancho El Mezquital | E16: Bomba de aspersion | F16: FIC-BOM-0014 | G16: 5400 | H16: 9800 | J16: No aplica | L16: Contado | M16: Tomas Iriarte | N16: =IFERROR(H16-G16,"") -> 4400 | O16: =IFERROR(N16/H16,"") -> 0.44897959 | P16: =IF($A16="","",IF(COUNTIF($A$3:$A16,$A16)=1,SUMIF(cobranza!$B$3:$B$1000,$A16,cobranza!$D$3:$D$1000),"↑")) -> 9800 | Q16: =IF($A16="","",IF(COUNTIF($A$3:$A16,$A16)=1,SUMIFS($H$3:$H$1000,$A$3:$A$1000,$A16,$C$3:$C$1000,"<>Demo")-P16,"↑")) -> 0
A17: V-015 | B17: 46205 | C17: Equipo | D17: Cooperativa Rio Verde | E17: AX-100 | F17: FIC-A100-0015 | G17: 380000 | H17: 520000 | I17: 0.05 | J17: Venta | K17: 60 | L17: Credito | M17: Mariana Olvera | N17: =IFERROR(H17-G17,"") -> 140000 | O17: =IFERROR(N17/H17,"") -> 0.26923077 | P17: =IF($A17="","",IF(COUNTIF($A$3:$A17,$A17)=1,SUMIF(cobranza!$B$3:$B$1000,$A17,cobranza!$D$3:$D$1000),"↑")) -> 431500 | Q17: =IF($A17="","",IF(COUNTIF($A$3:$A17,$A17)=1,SUMIFS($H$3:$H$1000,$A$3:$A$1000,$A17,$C$3:$C$1000,"<>Demo")-P17,"↑")) -> 100000
A18: V-015 | B18: 46205 | C18: Accesorios | D18: Cooperativa Rio Verde | E18: Bateria BX-30 | F18: FIC-BAT-0016 | G18: 6800 | H18: 11500 | J18: No aplica | L18: Contado | M18: Mariana Olvera | N18: =IFERROR(H18-G18,"") -> 4700 | O18: =IFERROR(N18/H18,"") -> 0.40869565 | P18: =IF($A18="","",IF(COUNTIF($A$3:$A18,$A18)=1,SUMIF(cobranza!$B$3:$B$1000,$A18,cobranza!$D$3:$D$1000),"↑")) -> ↑ | Q18: =IF($A18="","",IF(COUNTIF($A$3:$A18,$A18)=1,SUMIFS($H$3:$H$1000,$A$3:$A$1000,$A18,$C$3:$C$1000,"<>Demo")-P18,"↑")) -> ↑
A19: V-017 | B19: 46218 | C19: Equipo | D19: Agricola San Lorenzo | E19: AX-55 | F19: FIC-A055-0017 | G19: 190000 | H19: 265000 | J19: No aplica | K19: 90 | L19: Credito | M19: Mariana Olvera | N19: =IFERROR(H19-G19,"") -> 75000 | O19: =IFERROR(N19/H19,"") -> 0.28301887 | P19: =IF($A19="","",IF(COUNTIF($A$3:$A19,$A19)=1,SUMIF(cobranza!$B$3:$B$1000,$A19,cobranza!$D$3:$D$1000),"↑")) -> 150000 | Q19: =IF($A19="","",IF(COUNTIF($A$3:$A19,$A19)=1,SUMIFS($H$3:$H$1000,$A$3:$A$1000,$A19,$C$3:$C$1000,"<>Demo")-P19,"↑")) -> 115000
A20: V-018 | B20: 46224 | C20: Accesorios | D20: Agricola San Lorenzo | E20: Cargador rapido 80W | F20: FIC-CAR-0018 | G20: 3200 | H20: 5900 | J20: No aplica | L20: Contado | M20: Mariana Olvera | N20: =IFERROR(H20-G20,"") -> 2700 | O20: =IFERROR(N20/H20,"") -> 0.45762712 | P20: =IF($A20="","",IF(COUNTIF($A$3:$A20,$A20)=1,SUMIF(cobranza!$B$3:$B$1000,$A20,cobranza!$D$3:$D$1000),"↑")) -> 6100 | Q20: =IF($A20="","",IF(COUNTIF($A$3:$A20,$A20)=1,SUMIFS($H$3:$H$1000,$A$3:$A$1000,$A20,$C$3:$C$1000,"<>Demo")-P20,"↑")) -> -200
A21: V-019 | B21: 46232 | C21: Equipo | D21: Hortalizas La Esperanza | E21: AX-70 | F21: FIC-A070-0019 | G21: 295000 | H21: 385000 | I21: 0.05 | J21: Venta | K21: 90 | L21: Credito | M21: Tomas Iriarte | N21: =IFERROR(H21-G21,"") -> 90000 | O21: =IFERROR(N21/H21,"") -> 0.23376623 | P21: =IF($A21="","",IF(COUNTIF($A$3:$A21,$A21)=1,SUMIF(cobranza!$B$3:$B$1000,$A21,cobranza!$D$3:$D$1000),"↑")) -> 180000 | Q21: =IF($A21="","",IF(COUNTIF($A$3:$A21,$A21)=1,SUMIFS($H$3:$H$1000,$A$3:$A$1000,$A21,$C$3:$C$1000,"<>Demo")-P21,"↑")) -> 205000
A22: V-020 | B22: 46240 | C22: Servicio | D22: Finca Los Alamos | E22: Aplicacion 50 ha | G22: 18000 | H22: 32000 | J22: No aplica | L22: Contado | M22: Mariana Olvera | N22: =IFERROR(H22-G22,"") -> 14000 | O22: =IFERROR(N22/H22,"") -> 0.4375 | P22: =IF($A22="","",IF(COUNTIF($A$3:$A22,$A22)=1,SUMIF(cobranza!$B$3:$B$1000,$A22,cobranza!$D$3:$D$1000),"↑")) -> 32000 | Q22: =IF($A22="","",IF(COUNTIF($A$3:$A22,$A22)=1,SUMIFS($H$3:$H$1000,$A$3:$A$1000,$A22,$C$3:$C$1000,"<>Demo")-P22,"↑")) -> 0
A23: V-021 | B23: 46247 | C23: Equipo | D23: Agroservicios Tepeyac | E23: AX-25 | F23: FIC-A025-0021 | G23: 128000 | H23: 178000 | J23: No aplica | K23: 30 | L23: Credito | M23: Tomas Iriarte | N23: =IFERROR(H23-G23,"") -> 50000 | O23: =IFERROR(N23/H23,"") -> 0.28089888 | P23: =IF($A23="","",IF(COUNTIF($A$3:$A23,$A23)=1,SUMIF(cobranza!$B$3:$B$1000,$A23,cobranza!$D$3:$D$1000),"↑")) -> 80000 | Q23: =IF($A23="","",IF(COUNTIF($A$3:$A23,$A23)=1,SUMIFS($H$3:$H$1000,$A$3:$A$1000,$A23,$C$3:$C$1000,"<>Demo")-P23,"↑")) -> 98000
A24: V-022 | B24: 46258 | C24: Refacciones | D24: Campos de Altamira | E24: Kit de helices | F24: FIC-KIT-0022 | G24: 1900 | H24: 3600 | J24: No aplica | L24: Contado | M24: Tomas Iriarte | N24: =IFERROR(H24-G24,"") -> 1700 | O24: =IFERROR(N24/H24,"") -> 0.47222222 | P24: =IF($A24="","",IF(COUNTIF($A$3:$A24,$A24)=1,SUMIF(cobranza!$B$3:$B$1000,$A24,cobranza!$D$3:$D$1000),"↑")) -> 3600 | Q24: =IF($A24="","",IF(COUNTIF($A$3:$A24,$A24)=1,SUMIFS($H$3:$H$1000,$A$3:$A$1000,$A24,$C$3:$C$1000,"<>Demo")-P24,"↑")) -> 0
A25: V-023 | B25: 46266 | C25: Equipo | D25: Semillas del Norte | E25: AX-55 | F25: FIC-A055-0023 | G25: 190000 | H25: 265000 | J25: No aplica | L25: Credito | M25: Mariana Olvera | N25: =IFERROR(H25-G25,"") -> 75000 | O25: =IFERROR(N25/H25,"") -> 0.28301887 | P25: =IF($A25="","",IF(COUNTIF($A$3:$A25,$A25)=1,SUMIF(cobranza!$B$3:$B$1000,$A25,cobranza!$D$3:$D$1000),"↑")) -> 100000 | Q25: =IF($A25="","",IF(COUNTIF($A$3:$A25,$A25)=1,SUMIFS($H$3:$H$1000,$A$3:$A$1000,$A25,$C$3:$C$1000,"<>Demo")-P25,"↑")) -> 165000
A26: V-024 | B26: 46270 | C26: Accesorios | D26: Cooperativa Rio Verde | E26: Bateria BX-30 | F26: FIC-BAT-0024 | G26: 6800 | H26: 11500 | J26: No aplica | L26: Contado | M26: Mariana Olvera | N26: =IFERROR(H26-G26,"") -> 4700 | O26: =IFERROR(N26/H26,"") -> 0.40869565 | P26: =IF($A26="","",IF(COUNTIF($A$3:$A26,$A26)=1,SUMIF(cobranza!$B$3:$B$1000,$A26,cobranza!$D$3:$D$1000),"↑")) -> 11500 | Q26: =IF($A26="","",IF(COUNTIF($A$3:$A26,$A26)=1,SUMIFS($H$3:$H$1000,$A$3:$A$1000,$A26,$C$3:$C$1000,"<>Demo")-P26,"↑")) -> 0
A27: V-025 | C27: Refacciones | D27: Ing. Ramon Tellez | E27: Kit de helices | F27: FIC-KIT-0025 | G27: 1900 | H27: 3600 | J27: No aplica | L27: Contado | M27: Tomas Iriarte | N27: =IFERROR(H27-G27,"") -> 1700 | O27: =IFERROR(N27/H27,"") -> 0.47222222 | P27: =IF($A27="","",IF(COUNTIF($A$3:$A27,$A27)=1,SUMIF(cobranza!$B$3:$B$1000,$A27,cobranza!$D$3:$D$1000),"↑")) -> 3600 | Q27: =IF($A27="","",IF(COUNTIF($A$3:$A27,$A27)=1,SUMIFS($H$3:$H$1000,$A$3:$A$1000,$A27,$C$3:$C$1000,"<>Demo")-P27,"↑")) -> 0
N28: =IFERROR(H28-G28,"") -> 0 | O28: =IFERROR(N28/H28,"") | P28: =IF($A28="","",IF(COUNTIF($A$3:$A28,$A28)=1,SUMIF(cobranza!$B$3:$B$1000,$A28,cobranza!$D$3:$D$1000),"↑")) | Q28: =IF($A28="","",IF(COUNTIF($A$3:$A28,$A28)=1,SUMIFS($H$3:$H$1000,$A$3:$A$1000,$A28,$C$3:$C$1000,"<>Demo")-P28,"↑"))
N29: =IFERROR(H29-G29,"") -> 0 | O29: =IFERROR(N29/H29,"") | P29: =IF($A29="","",IF(COUNTIF($A$3:$A29,$A29)=1,SUMIF(cobranza!$B$3:$B$1000,$A29,cobranza!$D$3:$D$1000),"↑")) | Q29: =IF($A29="","",IF(COUNTIF($A$3:$A29,$A29)=1,SUMIFS($H$3:$H$1000,$A$3:$A$1000,$A29,$C$3:$C$1000,"<>Demo")-P29,"↑"))
N30: =IFERROR(H30-G30,"") -> 0 | O30: =IFERROR(N30/H30,"") | P30: =IF($A30="","",IF(COUNTIF($A$3:$A30,$A30)=1,SUMIF(cobranza!$B$3:$B$1000,$A30,cobranza!$D$3:$D$1000),"↑")) | Q30: =IF($A30="","",IF(COUNTIF($A$3:$A30,$A30)=1,SUMIFS($H$3:$H$1000,$A$3:$A$1000,$A30,$C$3:$C$1000,"<>Demo")-P30,"↑"))
N31: =IFERROR(H31-G31,"") -> 0 | O31: =IFERROR(N31/H31,"") | P31: =IF($A31="","",IF(COUNTIF($A$3:$A31,$A31)=1,SUMIF(cobranza!$B$3:$B$1000,$A31,cobranza!$D$3:$D$1000),"↑")) | Q31: =IF($A31="","",IF(COUNTIF($A$3:$A31,$A31)=1,SUMIFS($H$3:$H$1000,$A$3:$A$1000,$A31,$C$3:$C$1000,"<>Demo")-P31,"↑"))
N32: =IFERROR(H32-G32,"") -> 0 | O32: =IFERROR(N32/H32,"") | P32: =IF($A32="","",IF(COUNTIF($A$3:$A32,$A32)=1,SUMIF(cobranza!$B$3:$B$1000,$A32,cobranza!$D$3:$D$1000),"↑")) | Q32: =IF($A32="","",IF(COUNTIF($A$3:$A32,$A32)=1,SUMIFS($H$3:$H$1000,$A$3:$A$1000,$A32,$C$3:$C$1000,"<>Demo")-P32,"↑"))
N33: =IFERROR(H33-G33,"") -> 0 | O33: =IFERROR(N33/H33,"") | P33: =IF($A33="","",IF(COUNTIF($A$3:$A33,$A33)=1,SUMIF(cobranza!$B$3:$B$1000,$A33,cobranza!$D$3:$D$1000),"↑")) | Q33: =IF($A33="","",IF(COUNTIF($A$3:$A33,$A33)=1,SUMIFS($H$3:$H$1000,$A$3:$A$1000,$A33,$C$3:$C$1000,"<>Demo")-P33,"↑"))
N34: =IFERROR(H34-G34,"") -> 0 | O34: =IFERROR(N34/H34,"") | P34: =IF($A34="","",IF(COUNTIF($A$3:$A34,$A34)=1,SUMIF(cobranza!$B$3:$B$1000,$A34,cobranza!$D$3:$D$1000),"↑")) | Q34: =IF($A34="","",IF(COUNTIF($A$3:$A34,$A34)=1,SUMIFS($H$3:$H$1000,$A$3:$A$1000,$A34,$C$3:$C$1000,"<>Demo")-P34,"↑"))
N35: =IFERROR(H35-G35,"") -> 0 | O35: =IFERROR(N35/H35,"") | P35: =IF($A35="","",IF(COUNTIF($A$3:$A35,$A35)=1,SUMIF(cobranza!$B$3:$B$1000,$A35,cobranza!$D$3:$D$1000),"↑")) | Q35: =IF($A35="","",IF(COUNTIF($A$3:$A35,$A35)=1,SUMIFS($H$3:$H$1000,$A$3:$A$1000,$A35,$C$3:$C$1000,"<>Demo")-P35,"↑"))
N36: =IFERROR(H36-G36,"") -> 0 | O36: =IFERROR(N36/H36,"") | P36: =IF($A36="","",IF(COUNTIF($A$3:$A36,$A36)=1,SUMIF(cobranza!$B$3:$B$1000,$A36,cobranza!$D$3:$D$1000),"↑")) | Q36: =IF($A36="","",IF(COUNTIF($A$3:$A36,$A36)=1,SUMIFS($H$3:$H$1000,$A$3:$A$1000,$A36,$C$3:$C$1000,"<>Demo")-P36,"↑"))
N37: =IFERROR(H37-G37,"") -> 0 | O37: =IFERROR(N37/H37,"") | P37: =IF($A37="","",IF(COUNTIF($A$3:$A37,$A37)=1,SUMIF(cobranza!$B$3:$B$1000,$A37,cobranza!$D$3:$D$1000),"↑")) | Q37: =IF($A37="","",IF(COUNTIF($A$3:$A37,$A37)=1,SUMIFS($H$3:$H$1000,$A$3:$A$1000,$A37,$C$3:$C$1000,"<>Demo")-P37,"↑"))
N38: =IFERROR(H38-G38,"") -> 0 | O38: =IFERROR(N38/H38,"") | P38: =IF($A38="","",IF(COUNTIF($A$3:$A38,$A38)=1,SUMIF(cobranza!$B$3:$B$1000,$A38,cobranza!$D$3:$D$1000),"↑")) | Q38: =IF($A38="","",IF(COUNTIF($A$3:$A38,$A38)=1,SUMIFS($H$3:$H$1000,$A$3:$A$1000,$A38,$C$3:$C$1000,"<>Demo")-P38,"↑"))
N39: =IFERROR(H39-G39,"") -> 0 | O39: =IFERROR(N39/H39,"") | P39: =IF($A39="","",IF(COUNTIF($A$3:$A39,$A39)=1,SUMIF(cobranza!$B$3:$B$1000,$A39,cobranza!$D$3:$D$1000),"↑")) | Q39: =IF($A39="","",IF(COUNTIF($A$3:$A39,$A39)=1,SUMIFS($H$3:$H$1000,$A$3:$A$1000,$A39,$C$3:$C$1000,"<>Demo")-P39,"↑"))
... N301: =IFERROR(H301-G301,"") -> 0 | O301: =IFERROR(N301/H301,"") | P301: =IF($A301="","",IF(COUNTIF($A$3:$A301,$A301)=1,SUMIF(cobranza!$B$3:$B$1000,$A301,cobranza!$D$3:$D$1000),"↑")) | Q301: =IF($A301="","",IF(COUNTIF($A$3:$A301,$A301)=1,SUMIFS($H$3:$H$1000,$A$3:$A$1000,$A301,$C$3:$C$1000,"<>Demo")-P301,"↑"))

Sheet cobranza
A1: folio_pago | B1: folio_venta | C1: fecha_pago | D1: monto | E1: metodo | F1: cliente_ref | G1: notas
A2: P-000 | B2: V-000 | C2: 20/04/2026 | D2: 100000 | E2: Transferencia | F2: EJEMPLO — Cliente Demostrativo
A3: P-001 | B3: V-001 | C3: 46036 | D3: 120000 | E3: Transferencia | F3: Agricola San Lorenzo
A4: P-002 | B4: V-001 | C4: 46083 | D4: 80000 | E4: Transferencia | F4: Agricola San Lorenzo
A5: P-003 | B5: V-002 | C5: 46063 | D5: 90000 | E5: Deposito | F5: Rancho El Mezquital
A6: P-004 | B6: V-003 | C6: 46062 | D6: 150000 | E6: Transferencia | F6: Productores Unidos del Valle
A7: P-005 | B7: V-003 | C7: 46127 | D7: 60000 | E7: Cheque | F7: Productores Unidos del Valle
A8: P-006 | B8: V-004 | C8: 46062 | D8: 42000 | E8: Transferencia | F8: Vivero Santa Cruz
A9: P-007 | B9: V-005 | C9: 46073 | D9: 178000 | E9: Transferencia | F9: Hortalizas La Esperanza
A10: P-008 | B10: V-006 | C10: 46084 | D10: 295000 | E10: Transferencia | F10: Unidad demostrativa interna
A11: P-009 | B11: V-007 | C11: 46099 | D11: 200000 | E11: Transferencia | F11: Campos de Altamira
A12: P-010 | B12: V-007 | C12: 46178 | D12: 95000 | E12: Transferencia | F12: Campos de Altamira
A13: P-011 | B13: V-008 | C13: 46119 | D13: 100000 | E13: Transferencia | F13: Ing. Ramon Tellez
A14: P-012 | B14: V-008 | C14: 46119 | D14: 24000 | E14: Efectivo | F14: Ing. Ramon Tellez
... A24: P-022 | B24: V-017 | C24: 46218 | D24: 150000 | E24: Transferencia | F24: Agricola San Lorenzo
A25: P-023 | B25: V-018 | C25: 46224 | D25: 6100 | E25: Efectivo | F25: Agricola San Lorenzo | G25: Sobrecobro deliberado para prueba
A26: P-024 | B26: V-019 | C26: 46232 | D26: 180000 | E26: Transferencia | F26: Hortalizas La Esperanza
A27: P-025 | B27: V-020 | C27: 46240 | D27: 32000 | E27: Transferencia | F27: Finca Los Alamos
A28: P-026 | B28: V-021 | C28: 46247 | D28: 80000 | E28: Transferencia | F28: Agroservicios Tepeyac
A29: P-027 | B29: V-022 | C29: 46258 | D29: 3600 | E29: Efectivo | F29: Campos de Altamira
A30: P-028 | B30: V-023 | C30: 46266 | D30: 100000 | E30: Transferencia | F30: Semillas del Norte
A31: P-029 | B31: V-024 | C31: 46270 | D31: 11500 | E31: Efectivo | F31: Cooperativa Rio Verde
A32: P-030 | B32: V-025 | C32: 46264 | D32: 3600 | E32: Efectivo | F32: Ing. Ramon Tellez

Sheet gastos
A1: folio_gasto | B1: fecha | C1: categoria | D1: subcategoria | E1: descripcion | F1: monto | G1: tipo | H1: proveedor | I1: notas
A2: G-000 | B2: 10/03/2026 | C2: Nomina | D2: Sueldos | E2: Nomina mensual del personal | F2: 62000 | G2: Fijo | H2: N/A
A3: G-001 | B3: 46027 | C3: Renta | D3: Bodega | E3: Renta de bodega y oficina | F3: 13000 | G3: Fijo | H3: Inmuebles Bajio
A4: G-002 | B4: 46034 | C4: Servicios | D4: Electricidad | E4: Suministro electrico bodega | F4: 3600 | G4: Fijo | H4: CFE
A5: G-003 | B5: 46034 | C5: Servicios | D5: Conectividad | E5: Internet y telefonia movil | F5: 2400 | G5: Fijo | H5: Telecom Bajio
A6: G-004 | B6: 46039 | C6: Nomina | D6: IMSS | E6: Cuotas patronales IMSS e Infonavit | F6: 8200 | G6: Fijo
A7: G-005 | B7: 46042 | C7: Operativos | D7: Seguros | E7: Seguro de responsabilidad civil y equipo | F7: 4800 | G7: Fijo | H7: Aseguradora Ficticia
A8: G-006 | B8: 46044 | C8: Viaticos | D8: Combustible | E8: Combustible visitas a campo | F8: 8400 | G8: Variable
A9: G-007 | B9: 46050 | C9: Nomina | D9: Sueldos | E9: Nomina personal operativo y administrativo | F9: 38000 | G9: Fijo
A10: G-008 | B10: 46052 | C10: Financieros | D10: Comisiones | E10: Comisiones y manejo de cuenta bancaria | F10: 1200 | G10: Fijo | H10: Banco Ficticio
A11: G-009 | B11: 46052 | C11: Comercial | D11: Publicidad | E11: Campana digital temporada primavera | F11: 14500 | G11: Variable | H11: Agencia Ficticia
A12: G-010 | B12: 46058 | C12: Renta | D12: Bodega | E12: Renta de bodega y oficina | F12: 13000 | G12: Fijo | H12: Inmuebles Bajio
A13: G-011 | B13: 46064 | C13: Importacion | D13: Flete | E13: Flete internacional lote AX-100 | F13: 62000 | G13: Variable | H13: Logistica Ficticia
A14: G-012 | B14: 46064 | C14: Importacion | D14: Agente aduanal | E14: Honorarios agente aduanal lote AX-100 | F14: 23500 | G14: Variable | H14: Aduanas Ficticias
A15: G-013 | B15: 46065 | C15: Servicios | D15: Electricidad | E15: Suministro electrico bodega | F15: 3600 | G15: Fijo | H15: CFE
A16: G-014 | B16: 46065 | C16: Servicios | D16: Conectividad | E16: Internet y telefonia movil | F16: 2400 | G16: Fijo | H16: Telecom Bajio
A17: G-015 | B17: 46070 | C17: Nomina | D17: IMSS | E17: Cuotas patronales IMSS e Infonavit | F17: 8200 | G17: Fijo
A18: G-016 | B18: 46073 | C18: Operativos | D18: Seguros | E18: Seguro de responsabilidad civil y equipo | F18: 4800 | G18: Fijo | H18: Aseguradora Ficticia
A19: G-017 | B19: 46079 | C19: Comercial | D19: Demostraciones | E19: Demostracion en campo zona norte | F19: 11000 | G19: Variable
A20: G-018 | B20: 46081 | C20: Nomina | D20: Sueldos | E20: Nomina personal operativo y administrativo | F20: 38000 | G20: Fijo
A21: G-019 | B21: 46081 | C21: Financieros | D21: Comisiones | E21: Comisiones y manejo de cuenta bancaria | F21: 1200 | G21: Fijo | H21: Banco Ficticio
A22: G-020 | B22: 46086 | C22: Renta | D22: Bodega | E22: Renta de bodega y oficina | F22: 13000 | G22: Fijo | H22: Inmuebles Bajio
A23: G-021 | B23: 46093 | C23: Servicios | D23: Electricidad | E23: Suministro electrico bodega | F23: 3600 | G23: Fijo | H23: CFE
A24: G-022 | B24: 46093 | C24: Servicios | D24: Conectividad | E24: Internet y telefonia movil | F24: 2400 | G24: Fijo | H24: Telecom Bajio
A25: G-023 | B25: 46095 | C25: Viaticos | D25: Combustible | E25: Combustible visitas a campo | F25: 6900 | G25: Variable
A26: G-024 | B26: 46098 | C26: Nomina | D26: IMSS | E26: Cuotas patronales IMSS e Infonavit | F26: 8200 | G26: Fijo
A27: G-025 | B27: 46101 | C27: Operativos | D27: Seguros | E27: Seguro de responsabilidad civil y equipo | F27: 4800 | G27: Fijo | H27: Aseguradora Ficticia
A28: G-026 | B28: 46108 | C28: Operativos | D28: Mantenimiento | E28: Mantenimiento de unidades y taller | F28: 6200 | G28: Variable | H28: Taller Ficticio
A29: G-027 | B29: 46109 | C29: Nomina | D29: Sueldos | E29: Nomina personal operativo y administrativo | F29: 38000 | G29: Fijo
A30: G-028 | B30: 46111 | C30: Financieros | D30: Comisiones | E30: Comisiones y manejo de cuenta bancaria | F30: 1200 | G30: Fijo | H30: Banco Ficticio
A31: G-029 | B31: 46117 | C31: Renta | D31: Bodega | E31: Renta de bodega y oficina | F31: 13000 | G31: Fijo | H31: Inmuebles Bajio
A32: G-030 | B32: 46121 | C32: Comercial | D32: Eventos | E32: Expo agricola regional | F32: 16000 | G32: Variable
A33: G-031 | B33: 46122 | C33: Viaticos | D33: Hospedaje | E33: Hospedaje y alimentos expo | F33: 9800 | G33: Variable
A34: G-032 | B34: 46124 | C34: Servicios | D34: Electricidad | E34: Suministro electrico bodega | F34: 3600 | G34: Fijo | H34: CFE
A35: G-033 | B35: 46124 | C35: Servicios | D35: Conectividad | E35: Internet y telefonia movil | F35: 2400 | G35: Fijo | H35: Telecom Bajio
A36: G-034 | B36: 46129 | C36: Nomina | D36: IMSS | E36: Cuotas patronales IMSS e Infonavit | F36: 8200 | G36: Fijo
A37: G-035 | B37: 46132 | C37: Operativos | D37: Seguros | E37: Seguro de responsabilidad civil y equipo | F37: 4800 | G37: Fijo | H37: Aseguradora Ficticia
A38: G-036 | B38: 46140 | C38: Nomina | D38: Sueldos | E38: Nomina personal operativo y administrativo | F38: 38000 | G38: Fijo
A39: G-037 | B39: 46142 | C39: Financieros | D39: Comisiones | E39: Comisiones y manejo de cuenta bancaria | F39: 1200 | G39: Fijo | H39: Banco Ficticio
A40: G-038 | B40: 46147 | C40: Renta | D40: Bodega | E40: Renta de bodega y oficina | F40: 13000 | G40: Fijo | H40: Inmuebles Bajio
...

Sheet parametros
A1: parametro | B1: valor | C1: nota
A2: nombre_cliente | B2: Agrodrones del Bajio S.A. de C.V. (EMPRESA FICTICIA) | C2: Empresa ficticia. Aparece en la portada del reporte.
A3: moneda_base | B3: MXN | C3: Moneda de captura.
A4: importes_incluyen_iva | B4: NO | C4: Importes sin IVA.
A5: tasa_iva | B5: 0.16 | C5: Tasa aplicable.
A6: periodo_inicio | B6: 46023 | C6: Inicio del periodo.
A7: periodo_fin | B7: 46387 | C7: Fin del periodo.
A8: comision_base_default | B8: Venta | C8: Base por omision de la comision.
A9: dias_credito_default | B9: 90 | C9: Plazo estandar.
A10: provision_91_180 | B10: 0.25 | C10: % estimado incobrable 91-180 dias.
A11: provision_mas_180 | B11: 0.5 | C11: % estimado incobrable +180 dias.
A12: tipo_cambio_usd | B12: 18.4 | C12: Solo si se compra en USD.
